concurrent.futures.process._RemoteTraceback: 
"""
Traceback (most recent call last):
  File "F:\Anaconda_2025\envs\isac_dl\Lib\multiprocessing\queues.py", line 264, in _feed
    obj = _ForkingPickler.dumps(obj)
          ^^^^^^^^^^^^^^^^^^^^^^^^^^
  File "F:\Anaconda_2025\envs\isac_dl\Lib\multiprocessing\reduction.py", line 51, in dumps
    cls(buf, protocol).dump(obj)
AttributeError: Can't pickle local object 'run_milestone_m2.<locals>.<lambda>'
"""

The above exception was the direct cause of the following exception:

Traceback (most recent call last):
  File "F:\Github-repositories\RDT-VOI\src\main.py", line 385, in run_full_experiment
    m2_summary, all_results = run_milestone_m2(cfg, output_dir)
                              ^^^^^^^^^^^^^^^^^^^^^^^^^^^^^^^^^
  File "F:\Github-repositories\RDT-VOI\src\main.py", line 291, in run_milestone_m2
    cv_results = run_cv_experiment_parallel(
                 ^^^^^^^^^^^^^^^^^^^^^^^^^^^
  File "F:\Github-repositories\RDT-VOI\src\main.py", line 227, in run_cv_experiment_parallel
    fold_idx, metrics, selection_result = future.result()
                                          ^^^^^^^^^^^^^^^
  File "F:\Anaconda_2025\envs\isac_dl\Lib\concurrent\futures\_base.py", line 449, in result
    return self.__get_result()
           ^^^^^^^^^^^^^^^^^^^
  File "F:\Anaconda_2025\envs\isac_dl\Lib\concurrent\futures\_base.py", line 401, in __get_result
    raise self._exception
  File "F:\Anaconda_2025\envs\isac_dl\Lib\multiprocessing\queues.py", line 264, in _feed
    obj = _ForkingPickler.dumps(obj)
          ^^^^^^^^^^^^^^^^^^^^^^^^^^
  File "F:\Anaconda_2025\envs\isac_dl\Lib\multiprocessing\reduction.py", line 51, in dumps
    cls(buf, protocol).dump(obj)
AttributeError: Can't pickle local object 'run_milestone_m2.<locals>.<lambda>'
