Traceback (most recent call last):
  File "F:\Github-repositories\RDT-VOI\src\main.py", line 508, in run_full_experiment
    m2_summary, all_results = run_milestone_m2(cfg, output_dir)
                              ^^^^^^^^^^^^^^^^^^^^^^^^^^^^^^^^^
  File "F:\Github-repositories\RDT-VOI\src\main.py", line 414, in run_milestone_m2
    cv_results = run_cv_experiment_parallel(
                 ^^^^^^^^^^^^^^^^^^^^^^^^^^^
  File "F:\Github-repositories\RDT-VOI\src\main.py", line 248, in run_cv_experiment_parallel
    fold_idx, metrics = future.result()
                        ^^^^^^^^^^^^^^^
  File "F:\Anaconda_2025\envs\isac_dl\Lib\concurrent\futures\_base.py", line 449, in result
    return self.__get_result()
           ^^^^^^^^^^^^^^^^^^^
  File "F:\Anaconda_2025\envs\isac_dl\Lib\concurrent\futures\_base.py", line 401, in __get_result
    raise self._exception
concurrent.futures.process.BrokenProcessPool: A process in the process pool was terminated abruptly while the future was running or pending.
